<?xml version="1.0"?>
<robot name="robot" xmlns:xacro="http://www.ros.org/wiki/xacro">

<material name="grey">
 <color rgba="0.7 0.7 0.7 1"/>
</material>

<material name="green">
 <color rgba="0 0.6 0 1"/>
</material>

<material name="white">
<color rgba="1 1 1 1"/>
</material>

   <link name="base_link">
       <inertial>
          <mass value="5.0"/>
          <origin xyz="0 0 0" rpy="0 0 0"/>
          <inertia ixx="0.1" ixy="0.0" ixz="0.0" iyy="0.1" iyz="0.0" izz="0.1"/>
       </inertial>
       <visual>
          <geometry>
             <box size="0.6 0.4 0.1" />
          </geometry>
          <origin xyz="0 0 0" rpy="0 0 0"/>
          <material name="green"/>
       </visual>
       <collision>
         <geometry>
            <box size="0.6 0.4 0.1" />
         </geometry>
         <origin xyz="0 0 0" rpy="0 0 0"/>
       </collision>
   </link>

   <link name="lidar">
       <inertial>
          <mass value="0.2"/>
          <origin xyz="0 0 0" rpy="0 0 0"/>
          <inertia ixx="0.01" ixy="0.0" ixz="0.0" iyy="0.01" iyz="0.0" izz="0.01"/>
       </inertial>
       <visual>
          <geometry>
             <cylinder radius="0.05" length="0.05" />
          </geometry>
          <origin xyz="0 0 0" rpy="0 0 0"/>
          <material name="white"/>
       </visual>
       <collision>
         <geometry>
            <box size="0.1 0.1 0.05"/>
         </geometry>
         <origin xyz="0 0 0" rpy="0 0 0"/>
       </collision>
   </link>

   <xacro:macro name="wheel_link" params="prefix">
      <link name="${prefix}_wheel">
         <inertial>
            <mass value="0.5"/>
            <origin xyz="0 0 0" rpy="0 0 0"/>
            <inertia ixx="0.02" ixy="0.0" ixz="0.0" iyy="0.02" iyz="0.0" izz="0.02"/>
         </inertial>
         <visual>
            <geometry>
               <cylinder radius="0.1" length="0.1" />
            </geometry>
            <origin xyz="0 0 0" rpy="1.57 0 0"/>
            <material name="white"/>
         </visual>
         <collision>
           <geometry>
              <cylinder radius="0.1" length="0.1" />
           </geometry>
           <origin xyz="0 0 0" rpy="1.57 0 0"/>
         </collision>
     </link>
   </xacro:macro>
   
   <xacro:wheel_link prefix="left" />
   <xacro:wheel_link prefix="right" />
   <xacro:wheel_link prefix="left2" />
   <xacro:wheel_link prefix="right2" />


   <joint name="base_lidar_joint" type="fixed">
    <parent link="base_link"/>
    <child link="lidar"/>
    <origin xyz="0.2 0 0.075" rpy="0 0 0"/>
   </joint>

   <joint name="base_left_wheel_joint" type="continuous">
    <parent link="base_link"/>
    <child link="left_wheel"/>
    <origin xyz="-0.2 0.25 -0.1" rpy="0 0 0"/>
    <axis xyz="0 1 0"/>
   </joint>

   <joint name="base_left_wheel2_joint" type="continuous">
      <parent link="base_link"/>
      <child link="left2_wheel"/>
      <origin xyz="0.2 0.25 -0.1" rpy="0 0 0"/>
      <axis xyz="0 1 0"/>
   </joint>

   <joint name="base_right_wheel_joint" type="continuous">
    <parent link="base_link"/>
    <child link="right_wheel"/>
    <origin xyz="-0.2 -0.25 -0.1" rpy="0 0 0"/>
    <axis xyz="0 1 0"/>
   </joint>

   <joint name="base_right_wheel2_joint" type="continuous">
      <parent link="base_link"/>
      <child link="right2_wheel"/>
      <origin xyz="0.2 -0.25 -0.1" rpy="0 0 0"/>
      <axis xyz="0 1 0"/>
   </joint>

</robot>
