<?xml version="1.0"?>
<robot name="robot" xmlns:xacro="http://www.ros.org/wiki/xacro">

<material name="grey">
 <color rgba="0.7 0.7 0.7 1"/>
</material>

<material name="green">
 <color rgba="0 0.6 0 1"/>
</material>

<material name="white">
<color rgba="1 1 1 1"/>
</material>

   <link name="base_link">
       <inertial>
          <mass value="5.0"/>
          <origin xyz="0 0 0" rpy="0 0 0"/>
          <inertia ixx="0.1" ixy="0.0" ixz="0.0" iyy="0.1" iyz="0.0" izz="0.1"/>
       </inertial>
       <visual>
          <geometry>
             <box size="0.6 0.4 0.1" />
          </geometry>
          <origin xyz="0 0 0" rpy="0 0 0"/>
          <material name="green"/>
       </visual>
       <collision>
         <geometry>
            <box size="0.6 0.4 0.1" />
         </geometry>
         <origin xyz="0 0 0" rpy="0 0 0"/>
       </collision>
   </link>

   

   <xacro:macro name="wheel_link" params="prefix">
      <link name="${prefix}_wheel">
         <inertial>
            <mass value="0.5"/>
            <origin xyz="0 0 0" rpy="0 0 0"/>
            <inertia ixx="0.02" ixy="0.0" ixz="0.0" iyy="0.02" iyz="0.0" izz="0.02"/>
         </inertial>
         <visual>
            <geometry>
               <cylinder radius="0.1" length="0.1" />
            </geometry>
            <origin xyz="0 0 0" rpy="1.57 0 0"/>
            <material name="white"/>
         </visual>
         <collision>
           <geometry>
              <cylinder radius="0.1" length="0.1" />
           </geometry>
           <origin xyz="0 0 0" rpy="1.57 0 0"/>
         </collision>
     </link>
   </xacro:macro>
   
   <xacro:wheel_link prefix="left" />
   <xacro:wheel_link prefix="right" />
   <xacro:wheel_link prefix="left2" />
   <xacro:wheel_link prefix="right2" />


   <joint name="base_left_wheel_joint" type="continuous">
    <parent link="base_link"/>
    <child link="left_wheel"/>
    <origin xyz="-0.2 0.25 -0.1" rpy="0 0 0"/>
    <axis xyz="0 1 0"/>
   </joint>

   <joint name="base_left_wheel2_joint" type="continuous">
      <parent link="base_link"/>
      <child link="left2_wheel"/>
      <origin xyz="0.2 0.25 -0.1" rpy="0 0 0"/>
      <axis xyz="0 1 0"/>
   </joint>

   <joint name="base_right_wheel_joint" type="continuous">
    <parent link="base_link"/>
    <child link="right_wheel"/>
    <origin xyz="-0.2 -0.25 -0.1" rpy="0 0 0"/>
    <axis xyz="0 1 0"/>
   </joint>

   <joint name="base_right_wheel2_joint" type="continuous">
      <parent link="base_link"/>
      <child link="right2_wheel"/>
      <origin xyz="0.2 -0.25 -0.1" rpy="0 0 0"/>
      <axis xyz="0 1 0"/>
   </joint>

   <gazebo>
	    <plugin name="front_wheel" filename="libgazebo_ros_diff_drive.so">
    	<!-- Wheel Information -->
        <left_joint>base_left_wheel_joint</left_joint>
        <right_joint>base_right_wheel_joint</right_joint>
        <wheel_separation>0.064</wheel_separation>
        <wheel_diameter>0.1</wheel_diameter>
 
        <!-- Limit -->
        <max_wheel_torque>200</max_wheel_torque>
        <max_wheel_acceleration>10.0</max_wheel_acceleration>
 
        <!-- Output -->
        <odometry_frame>odom</odometry_frame>
        <robot_base_frame>base_link</robot_base_frame>
 
        <publish_odom>true</publish_odom>
        <publish_odom_tf>true</publish_odom_tf>
        <publish_wheel_tf>true</publish_wheel_tf>
 
	</plugin>
  	</gazebo>

	<gazebo>
	  <plugin name="rear_wheel" filename="libgazebo_ros_diff_drive.so">
    	<!-- Wheel Information -->
        <left_joint>base_left_wheel2_joint</left_joint>
        <right_joint>base_right_wheel2_joint</right_joint>
        <wheel_separation>0.064</wheel_separation>
        <wheel_diameter>0.1</wheel_diameter>
 
        <!-- Limit -->
        <max_wheel_torque>200</max_wheel_torque>
        <max_wheel_acceleration>10.0</max_wheel_acceleration>
 
        <!-- Output -->
        <odometry_frame>odom</odometry_frame>
        <robot_base_frame>base_link</robot_base_frame>
 
        <publish_odom>true</publish_odom>
        <publish_odom_tf>true</publish_odom_tf>
        <publish_wheel_tf>true</publish_wheel_tf>
 
	  </plugin>
  	
</gazebo>


</robot>
